[2025-09-16T15:56:55.771+0000] {taskinstance.py:1157} INFO - Dependencies all met for dep_context=non-requeueable deps ti=<TaskInstance: crypto_pipeline_postgres.load scheduled__2025-09-15T00:00:00+00:00 [queued]>
[2025-09-16T15:56:55.776+0000] {taskinstance.py:1157} INFO - Dependencies all met for dep_context=requeueable deps ti=<TaskInstance: crypto_pipeline_postgres.load scheduled__2025-09-15T00:00:00+00:00 [queued]>
[2025-09-16T15:56:55.776+0000] {taskinstance.py:1359} INFO - Starting attempt 2 of 2
[2025-09-16T15:56:55.784+0000] {taskinstance.py:1380} INFO - Executing <Task(PythonOperator): load> on 2025-09-15 00:00:00+00:00
[2025-09-16T15:56:55.787+0000] {standard_task_runner.py:57} INFO - Started process 207 to run task
[2025-09-16T15:56:55.789+0000] {standard_task_runner.py:84} INFO - Running: ['***', 'tasks', 'run', 'crypto_pipeline_postgres', 'load', 'scheduled__2025-09-15T00:00:00+00:00', '--job-id', '15', '--raw', '--subdir', 'DAGS_FOLDER/coleta_dados.py', '--cfg-path', '/tmp/tmppxoore3s']
[2025-09-16T15:56:55.791+0000] {standard_task_runner.py:85} INFO - Job 15: Subtask load
[2025-09-16T15:56:55.819+0000] {task_command.py:415} INFO - Running <TaskInstance: crypto_pipeline_postgres.load scheduled__2025-09-15T00:00:00+00:00 [running]> on host f0ba1f59a373
[2025-09-16T15:56:55.871+0000] {taskinstance.py:1660} INFO - Exporting env vars: AIRFLOW_CTX_DAG_OWNER='***' AIRFLOW_CTX_DAG_ID='crypto_pipeline_postgres' AIRFLOW_CTX_TASK_ID='load' AIRFLOW_CTX_EXECUTION_DATE='2025-09-15T00:00:00+00:00' AIRFLOW_CTX_TRY_NUMBER='2' AIRFLOW_CTX_DAG_RUN_ID='scheduled__2025-09-15T00:00:00+00:00'
[2025-09-16T15:56:55.887+0000] {taskinstance.py:1935} ERROR - Task failed with exception
Traceback (most recent call last):
  File "/home/airflow/.local/lib/python3.8/site-packages/airflow/operators/python.py", line 192, in execute
    return_value = self.execute_callable()
  File "/home/airflow/.local/lib/python3.8/site-packages/airflow/operators/python.py", line 209, in execute_callable
    return self.python_callable(*self.op_args, **self.op_kwargs)
  File "/opt/airflow/dags/coleta_dados.py", line 31, in carregar_dados
    engine = hook.get_sqlalchemy_engine()
  File "/home/airflow/.local/lib/python3.8/site-packages/airflow/providers/common/sql/hooks/sql.py", line 199, in get_sqlalchemy_engine
    return create_engine(self.get_uri(), **engine_kwargs)
  File "/home/airflow/.local/lib/python3.8/site-packages/airflow/providers/postgres/hooks/postgres.py", line 185, in get_uri
    conn = self.get_connection(getattr(self, self.conn_name_attr))
  File "/home/airflow/.local/lib/python3.8/site-packages/airflow/hooks/base.py", line 72, in get_connection
    conn = Connection.get_connection_from_secrets(conn_id)
  File "/home/airflow/.local/lib/python3.8/site-packages/airflow/models/connection.py", line 477, in get_connection_from_secrets
    raise AirflowNotFoundException(f"The conn_id `{conn_id}` isn't defined")
airflow.exceptions.AirflowNotFoundException: The conn_id `postgres_default` isn't defined
[2025-09-16T15:56:55.889+0000] {taskinstance.py:1398} INFO - Marking task as FAILED. dag_id=crypto_pipeline_postgres, task_id=load, execution_date=20250915T000000, start_date=20250916T155655, end_date=20250916T155655
[2025-09-16T15:56:55.896+0000] {standard_task_runner.py:104} ERROR - Failed to execute job 15 for task load (The conn_id `postgres_default` isn't defined; 207)
[2025-09-16T15:56:55.921+0000] {local_task_job_runner.py:228} INFO - Task exited with return code 1
[2025-09-16T15:56:55.932+0000] {taskinstance.py:2776} INFO - 0 downstream tasks scheduled from follow-on schedule check
[2025-09-16T16:08:04.454+0000] {taskinstance.py:1157} INFO - Dependencies all met for dep_context=non-requeueable deps ti=<TaskInstance: crypto_pipeline_postgres.load scheduled__2025-09-15T00:00:00+00:00 [queued]>
[2025-09-16T16:08:04.459+0000] {taskinstance.py:1157} INFO - Dependencies all met for dep_context=requeueable deps ti=<TaskInstance: crypto_pipeline_postgres.load scheduled__2025-09-15T00:00:00+00:00 [queued]>
[2025-09-16T16:08:04.459+0000] {taskinstance.py:1359} INFO - Starting attempt 2 of 2
[2025-09-16T16:08:04.468+0000] {taskinstance.py:1380} INFO - Executing <Task(PythonOperator): load> on 2025-09-15 00:00:00+00:00
[2025-09-16T16:08:04.472+0000] {standard_task_runner.py:57} INFO - Started process 205 to run task
[2025-09-16T16:08:04.474+0000] {standard_task_runner.py:84} INFO - Running: ['***', 'tasks', 'run', 'crypto_pipeline_postgres', 'load', 'scheduled__2025-09-15T00:00:00+00:00', '--job-id', '11', '--raw', '--subdir', 'DAGS_FOLDER/coleta_dados.py', '--cfg-path', '/tmp/tmp567h0r9s']
[2025-09-16T16:08:04.475+0000] {standard_task_runner.py:85} INFO - Job 11: Subtask load
[2025-09-16T16:08:04.505+0000] {task_command.py:415} INFO - Running <TaskInstance: crypto_pipeline_postgres.load scheduled__2025-09-15T00:00:00+00:00 [running]> on host 529eb878ec8c
[2025-09-16T16:08:04.551+0000] {taskinstance.py:1660} INFO - Exporting env vars: AIRFLOW_CTX_DAG_OWNER='***' AIRFLOW_CTX_DAG_ID='crypto_pipeline_postgres' AIRFLOW_CTX_TASK_ID='load' AIRFLOW_CTX_EXECUTION_DATE='2025-09-15T00:00:00+00:00' AIRFLOW_CTX_TRY_NUMBER='2' AIRFLOW_CTX_DAG_RUN_ID='scheduled__2025-09-15T00:00:00+00:00'
[2025-09-16T16:08:04.566+0000] {taskinstance.py:1935} ERROR - Task failed with exception
Traceback (most recent call last):
  File "/home/airflow/.local/lib/python3.8/site-packages/airflow/operators/python.py", line 192, in execute
    return_value = self.execute_callable()
  File "/home/airflow/.local/lib/python3.8/site-packages/airflow/operators/python.py", line 209, in execute_callable
    return self.python_callable(*self.op_args, **self.op_kwargs)
  File "/opt/airflow/dags/coleta_dados.py", line 49, in carregar_dados
    engine = hook.get_sqlalchemy_engine()
  File "/home/airflow/.local/lib/python3.8/site-packages/airflow/providers/common/sql/hooks/sql.py", line 199, in get_sqlalchemy_engine
    return create_engine(self.get_uri(), **engine_kwargs)
  File "/home/airflow/.local/lib/python3.8/site-packages/airflow/providers/postgres/hooks/postgres.py", line 185, in get_uri
    conn = self.get_connection(getattr(self, self.conn_name_attr))
  File "/home/airflow/.local/lib/python3.8/site-packages/airflow/hooks/base.py", line 72, in get_connection
    conn = Connection.get_connection_from_secrets(conn_id)
  File "/home/airflow/.local/lib/python3.8/site-packages/airflow/models/connection.py", line 477, in get_connection_from_secrets
    raise AirflowNotFoundException(f"The conn_id `{conn_id}` isn't defined")
airflow.exceptions.AirflowNotFoundException: The conn_id `postgres_default` isn't defined
[2025-09-16T16:08:04.569+0000] {taskinstance.py:1398} INFO - Marking task as FAILED. dag_id=crypto_pipeline_postgres, task_id=load, execution_date=20250915T000000, start_date=20250916T160804, end_date=20250916T160804
[2025-09-16T16:08:04.577+0000] {standard_task_runner.py:104} ERROR - Failed to execute job 11 for task load (The conn_id `postgres_default` isn't defined; 205)
[2025-09-16T16:08:04.605+0000] {local_task_job_runner.py:228} INFO - Task exited with return code 1
[2025-09-16T16:08:04.617+0000] {taskinstance.py:2776} INFO - 0 downstream tasks scheduled from follow-on schedule check
[2025-09-16T16:19:15.301+0000] {taskinstance.py:1157} INFO - Dependencies all met for dep_context=non-requeueable deps ti=<TaskInstance: crypto_pipeline_postgres.load scheduled__2025-09-15T00:00:00+00:00 [queued]>
[2025-09-16T16:19:15.307+0000] {taskinstance.py:1157} INFO - Dependencies all met for dep_context=requeueable deps ti=<TaskInstance: crypto_pipeline_postgres.load scheduled__2025-09-15T00:00:00+00:00 [queued]>
[2025-09-16T16:19:15.307+0000] {taskinstance.py:1359} INFO - Starting attempt 2 of 2
[2025-09-16T16:19:15.315+0000] {taskinstance.py:1380} INFO - Executing <Task(PythonOperator): load> on 2025-09-15 00:00:00+00:00
[2025-09-16T16:19:15.320+0000] {standard_task_runner.py:57} INFO - Started process 162 to run task
[2025-09-16T16:19:15.322+0000] {standard_task_runner.py:84} INFO - Running: ['***', 'tasks', 'run', 'crypto_pipeline_postgres', 'load', 'scheduled__2025-09-15T00:00:00+00:00', '--job-id', '8', '--raw', '--subdir', 'DAGS_FOLDER/coleta_dados.py', '--cfg-path', '/tmp/tmpfz9d1up5']
[2025-09-16T16:19:15.323+0000] {standard_task_runner.py:85} INFO - Job 8: Subtask load
[2025-09-16T16:19:15.354+0000] {task_command.py:415} INFO - Running <TaskInstance: crypto_pipeline_postgres.load scheduled__2025-09-15T00:00:00+00:00 [running]> on host 5a564937ffb3
[2025-09-16T16:19:15.399+0000] {taskinstance.py:1660} INFO - Exporting env vars: AIRFLOW_CTX_DAG_OWNER='***' AIRFLOW_CTX_DAG_ID='crypto_pipeline_postgres' AIRFLOW_CTX_TASK_ID='load' AIRFLOW_CTX_EXECUTION_DATE='2025-09-15T00:00:00+00:00' AIRFLOW_CTX_TRY_NUMBER='2' AIRFLOW_CTX_DAG_RUN_ID='scheduled__2025-09-15T00:00:00+00:00'
[2025-09-16T16:19:15.401+0000] {taskinstance.py:1935} ERROR - Task failed with exception
Traceback (most recent call last):
  File "/home/airflow/.local/lib/python3.8/site-packages/airflow/operators/python.py", line 192, in execute
    return_value = self.execute_callable()
  File "/home/airflow/.local/lib/python3.8/site-packages/airflow/operators/python.py", line 209, in execute_callable
    return self.python_callable(*self.op_args, **self.op_kwargs)
  File "/opt/airflow/dags/coleta_dados.py", line 63, in carregar_dados
    df = pd.read_csv(TRANSFORMED_CSV_PATH)
  File "/home/airflow/.local/lib/python3.8/site-packages/pandas/io/parsers/readers.py", line 912, in read_csv
    return _read(filepath_or_buffer, kwds)
  File "/home/airflow/.local/lib/python3.8/site-packages/pandas/io/parsers/readers.py", line 577, in _read
    parser = TextFileReader(filepath_or_buffer, **kwds)
  File "/home/airflow/.local/lib/python3.8/site-packages/pandas/io/parsers/readers.py", line 1407, in __init__
    self._engine = self._make_engine(f, self.engine)
  File "/home/airflow/.local/lib/python3.8/site-packages/pandas/io/parsers/readers.py", line 1661, in _make_engine
    self.handles = get_handle(
  File "/home/airflow/.local/lib/python3.8/site-packages/pandas/io/common.py", line 859, in get_handle
    handle = open(
FileNotFoundError: [Errno 2] No such file or directory: '/tmp/crypto_transformed.csv'
[2025-09-16T16:19:15.407+0000] {taskinstance.py:1398} INFO - Marking task as FAILED. dag_id=crypto_pipeline_postgres, task_id=load, execution_date=20250915T000000, start_date=20250916T161915, end_date=20250916T161915
[2025-09-16T16:19:15.413+0000] {standard_task_runner.py:104} ERROR - Failed to execute job 8 for task load ([Errno 2] No such file or directory: '/tmp/crypto_transformed.csv'; 162)
[2025-09-16T16:19:15.454+0000] {local_task_job_runner.py:228} INFO - Task exited with return code 1
[2025-09-16T16:19:15.466+0000] {taskinstance.py:2776} INFO - 0 downstream tasks scheduled from follow-on schedule check
