[2025-09-16T15:51:53.642+0000] {taskinstance.py:1157} INFO - Dependencies all met for dep_context=non-requeueable deps ti=<TaskInstance: crypto_pipeline_postgres.load scheduled__2025-09-15T00:00:00+00:00 [queued]>
[2025-09-16T15:51:53.646+0000] {taskinstance.py:1157} INFO - Dependencies all met for dep_context=requeueable deps ti=<TaskInstance: crypto_pipeline_postgres.load scheduled__2025-09-15T00:00:00+00:00 [queued]>
[2025-09-16T15:51:53.647+0000] {taskinstance.py:1359} INFO - Starting attempt 1 of 2
[2025-09-16T15:51:53.654+0000] {taskinstance.py:1380} INFO - Executing <Task(PythonOperator): load> on 2025-09-15 00:00:00+00:00
[2025-09-16T15:51:53.659+0000] {standard_task_runner.py:57} INFO - Started process 114 to run task
[2025-09-16T15:51:53.661+0000] {standard_task_runner.py:84} INFO - Running: ['***', 'tasks', 'run', 'crypto_pipeline_postgres', 'load', 'scheduled__2025-09-15T00:00:00+00:00', '--job-id', '10', '--raw', '--subdir', 'DAGS_FOLDER/coleta_dados.py', '--cfg-path', '/tmp/tmpd2t4ctly']
[2025-09-16T15:51:53.662+0000] {standard_task_runner.py:85} INFO - Job 10: Subtask load
[2025-09-16T15:51:53.691+0000] {task_command.py:415} INFO - Running <TaskInstance: crypto_pipeline_postgres.load scheduled__2025-09-15T00:00:00+00:00 [running]> on host f0ba1f59a373
[2025-09-16T15:51:53.736+0000] {taskinstance.py:1660} INFO - Exporting env vars: AIRFLOW_CTX_DAG_OWNER='***' AIRFLOW_CTX_DAG_ID='crypto_pipeline_postgres' AIRFLOW_CTX_TASK_ID='load' AIRFLOW_CTX_EXECUTION_DATE='2025-09-15T00:00:00+00:00' AIRFLOW_CTX_TRY_NUMBER='1' AIRFLOW_CTX_DAG_RUN_ID='scheduled__2025-09-15T00:00:00+00:00'
[2025-09-16T15:51:53.752+0000] {taskinstance.py:1935} ERROR - Task failed with exception
Traceback (most recent call last):
  File "/home/airflow/.local/lib/python3.8/site-packages/airflow/operators/python.py", line 192, in execute
    return_value = self.execute_callable()
  File "/home/airflow/.local/lib/python3.8/site-packages/airflow/operators/python.py", line 209, in execute_callable
    return self.python_callable(*self.op_args, **self.op_kwargs)
  File "/opt/airflow/dags/coleta_dados.py", line 31, in carregar_dados
    engine = hook.get_sqlalchemy_engine()
  File "/home/airflow/.local/lib/python3.8/site-packages/airflow/providers/common/sql/hooks/sql.py", line 199, in get_sqlalchemy_engine
    return create_engine(self.get_uri(), **engine_kwargs)
  File "/home/airflow/.local/lib/python3.8/site-packages/airflow/providers/postgres/hooks/postgres.py", line 185, in get_uri
    conn = self.get_connection(getattr(self, self.conn_name_attr))
  File "/home/airflow/.local/lib/python3.8/site-packages/airflow/hooks/base.py", line 72, in get_connection
    conn = Connection.get_connection_from_secrets(conn_id)
  File "/home/airflow/.local/lib/python3.8/site-packages/airflow/models/connection.py", line 477, in get_connection_from_secrets
    raise AirflowNotFoundException(f"The conn_id `{conn_id}` isn't defined")
airflow.exceptions.AirflowNotFoundException: The conn_id `postgres_default` isn't defined
[2025-09-16T15:51:53.754+0000] {taskinstance.py:1398} INFO - Marking task as UP_FOR_RETRY. dag_id=crypto_pipeline_postgres, task_id=load, execution_date=20250915T000000, start_date=20250916T155153, end_date=20250916T155153
[2025-09-16T15:51:53.762+0000] {standard_task_runner.py:104} ERROR - Failed to execute job 10 for task load (The conn_id `postgres_default` isn't defined; 114)
[2025-09-16T15:51:53.792+0000] {local_task_job_runner.py:228} INFO - Task exited with return code 1
[2025-09-16T15:51:53.804+0000] {taskinstance.py:2776} INFO - 0 downstream tasks scheduled from follow-on schedule check
[2025-09-16T16:03:01.936+0000] {taskinstance.py:1157} INFO - Dependencies all met for dep_context=non-requeueable deps ti=<TaskInstance: crypto_pipeline_postgres.load scheduled__2025-09-15T00:00:00+00:00 [queued]>
[2025-09-16T16:03:01.941+0000] {taskinstance.py:1157} INFO - Dependencies all met for dep_context=requeueable deps ti=<TaskInstance: crypto_pipeline_postgres.load scheduled__2025-09-15T00:00:00+00:00 [queued]>
[2025-09-16T16:03:01.941+0000] {taskinstance.py:1359} INFO - Starting attempt 1 of 2
[2025-09-16T16:03:01.949+0000] {taskinstance.py:1380} INFO - Executing <Task(PythonOperator): load> on 2025-09-15 00:00:00+00:00
[2025-09-16T16:03:01.954+0000] {standard_task_runner.py:57} INFO - Started process 110 to run task
[2025-09-16T16:03:01.956+0000] {standard_task_runner.py:84} INFO - Running: ['***', 'tasks', 'run', 'crypto_pipeline_postgres', 'load', 'scheduled__2025-09-15T00:00:00+00:00', '--job-id', '6', '--raw', '--subdir', 'DAGS_FOLDER/coleta_dados.py', '--cfg-path', '/tmp/tmp17e3lg5r']
[2025-09-16T16:03:01.957+0000] {standard_task_runner.py:85} INFO - Job 6: Subtask load
[2025-09-16T16:03:01.986+0000] {task_command.py:415} INFO - Running <TaskInstance: crypto_pipeline_postgres.load scheduled__2025-09-15T00:00:00+00:00 [running]> on host 529eb878ec8c
[2025-09-16T16:03:02.032+0000] {taskinstance.py:1660} INFO - Exporting env vars: AIRFLOW_CTX_DAG_OWNER='***' AIRFLOW_CTX_DAG_ID='crypto_pipeline_postgres' AIRFLOW_CTX_TASK_ID='load' AIRFLOW_CTX_EXECUTION_DATE='2025-09-15T00:00:00+00:00' AIRFLOW_CTX_TRY_NUMBER='1' AIRFLOW_CTX_DAG_RUN_ID='scheduled__2025-09-15T00:00:00+00:00'
[2025-09-16T16:03:02.047+0000] {taskinstance.py:1935} ERROR - Task failed with exception
Traceback (most recent call last):
  File "/home/airflow/.local/lib/python3.8/site-packages/airflow/operators/python.py", line 192, in execute
    return_value = self.execute_callable()
  File "/home/airflow/.local/lib/python3.8/site-packages/airflow/operators/python.py", line 209, in execute_callable
    return self.python_callable(*self.op_args, **self.op_kwargs)
  File "/opt/airflow/dags/coleta_dados.py", line 32, in carregar_dados
    engine = hook.get_sqlalchemy_engine()
  File "/home/airflow/.local/lib/python3.8/site-packages/airflow/providers/common/sql/hooks/sql.py", line 199, in get_sqlalchemy_engine
    return create_engine(self.get_uri(), **engine_kwargs)
  File "/home/airflow/.local/lib/python3.8/site-packages/airflow/providers/postgres/hooks/postgres.py", line 185, in get_uri
    conn = self.get_connection(getattr(self, self.conn_name_attr))
  File "/home/airflow/.local/lib/python3.8/site-packages/airflow/hooks/base.py", line 72, in get_connection
    conn = Connection.get_connection_from_secrets(conn_id)
  File "/home/airflow/.local/lib/python3.8/site-packages/airflow/models/connection.py", line 477, in get_connection_from_secrets
    raise AirflowNotFoundException(f"The conn_id `{conn_id}` isn't defined")
airflow.exceptions.AirflowNotFoundException: The conn_id `postgres_default` isn't defined
[2025-09-16T16:03:02.049+0000] {taskinstance.py:1398} INFO - Marking task as UP_FOR_RETRY. dag_id=crypto_pipeline_postgres, task_id=load, execution_date=20250915T000000, start_date=20250916T160301, end_date=20250916T160302
[2025-09-16T16:03:02.056+0000] {standard_task_runner.py:104} ERROR - Failed to execute job 6 for task load (The conn_id `postgres_default` isn't defined; 110)
[2025-09-16T16:03:02.087+0000] {local_task_job_runner.py:228} INFO - Task exited with return code 1
[2025-09-16T16:03:02.099+0000] {taskinstance.py:2776} INFO - 0 downstream tasks scheduled from follow-on schedule check
[2025-09-16T16:14:12.517+0000] {taskinstance.py:1157} INFO - Dependencies all met for dep_context=non-requeueable deps ti=<TaskInstance: crypto_pipeline_postgres.load scheduled__2025-09-15T00:00:00+00:00 [queued]>
[2025-09-16T16:14:12.522+0000] {taskinstance.py:1157} INFO - Dependencies all met for dep_context=requeueable deps ti=<TaskInstance: crypto_pipeline_postgres.load scheduled__2025-09-15T00:00:00+00:00 [queued]>
[2025-09-16T16:14:12.522+0000] {taskinstance.py:1359} INFO - Starting attempt 1 of 2
[2025-09-16T16:14:12.530+0000] {taskinstance.py:1380} INFO - Executing <Task(PythonOperator): load> on 2025-09-15 00:00:00+00:00
[2025-09-16T16:14:12.535+0000] {standard_task_runner.py:57} INFO - Started process 110 to run task
[2025-09-16T16:14:12.537+0000] {standard_task_runner.py:84} INFO - Running: ['***', 'tasks', 'run', 'crypto_pipeline_postgres', 'load', 'scheduled__2025-09-15T00:00:00+00:00', '--job-id', '6', '--raw', '--subdir', 'DAGS_FOLDER/coleta_dados.py', '--cfg-path', '/tmp/tmpo454zv4b']
[2025-09-16T16:14:12.538+0000] {standard_task_runner.py:85} INFO - Job 6: Subtask load
[2025-09-16T16:14:12.567+0000] {task_command.py:415} INFO - Running <TaskInstance: crypto_pipeline_postgres.load scheduled__2025-09-15T00:00:00+00:00 [running]> on host 5a564937ffb3
[2025-09-16T16:14:12.611+0000] {taskinstance.py:1660} INFO - Exporting env vars: AIRFLOW_CTX_DAG_OWNER='***' AIRFLOW_CTX_DAG_ID='crypto_pipeline_postgres' AIRFLOW_CTX_TASK_ID='load' AIRFLOW_CTX_EXECUTION_DATE='2025-09-15T00:00:00+00:00' AIRFLOW_CTX_TRY_NUMBER='1' AIRFLOW_CTX_DAG_RUN_ID='scheduled__2025-09-15T00:00:00+00:00'
[2025-09-16T16:14:12.633+0000] {taskinstance.py:1935} ERROR - Task failed with exception
Traceback (most recent call last):
  File "/home/airflow/.local/lib/python3.8/site-packages/airflow/operators/python.py", line 192, in execute
    return_value = self.execute_callable()
  File "/home/airflow/.local/lib/python3.8/site-packages/airflow/operators/python.py", line 209, in execute_callable
    return self.python_callable(*self.op_args, **self.op_kwargs)
  File "/opt/airflow/dags/coleta_dados.py", line 71, in carregar_dados
    engine = hook.get_sqlalchemy_engine()
  File "/home/airflow/.local/lib/python3.8/site-packages/airflow/providers/common/sql/hooks/sql.py", line 199, in get_sqlalchemy_engine
    return create_engine(self.get_uri(), **engine_kwargs)
  File "/home/airflow/.local/lib/python3.8/site-packages/airflow/providers/postgres/hooks/postgres.py", line 185, in get_uri
    conn = self.get_connection(getattr(self, self.conn_name_attr))
  File "/home/airflow/.local/lib/python3.8/site-packages/airflow/hooks/base.py", line 72, in get_connection
    conn = Connection.get_connection_from_secrets(conn_id)
  File "/home/airflow/.local/lib/python3.8/site-packages/airflow/models/connection.py", line 477, in get_connection_from_secrets
    raise AirflowNotFoundException(f"The conn_id `{conn_id}` isn't defined")
airflow.exceptions.AirflowNotFoundException: The conn_id `postgres_default` isn't defined
[2025-09-16T16:14:12.636+0000] {taskinstance.py:1398} INFO - Marking task as UP_FOR_RETRY. dag_id=crypto_pipeline_postgres, task_id=load, execution_date=20250915T000000, start_date=20250916T161412, end_date=20250916T161412
[2025-09-16T16:14:12.642+0000] {standard_task_runner.py:104} ERROR - Failed to execute job 6 for task load (The conn_id `postgres_default` isn't defined; 110)
[2025-09-16T16:14:12.668+0000] {local_task_job_runner.py:228} INFO - Task exited with return code 1
[2025-09-16T16:14:12.680+0000] {taskinstance.py:2776} INFO - 0 downstream tasks scheduled from follow-on schedule check
[2025-09-16T16:23:34.187+0000] {taskinstance.py:1157} INFO - Dependencies all met for dep_context=non-requeueable deps ti=<TaskInstance: crypto_pipeline_postgres.load scheduled__2025-09-15T00:00:00+00:00 [queued]>
[2025-09-16T16:23:34.192+0000] {taskinstance.py:1157} INFO - Dependencies all met for dep_context=requeueable deps ti=<TaskInstance: crypto_pipeline_postgres.load scheduled__2025-09-15T00:00:00+00:00 [queued]>
[2025-09-16T16:23:34.193+0000] {taskinstance.py:1359} INFO - Starting attempt 1 of 2
[2025-09-16T16:23:34.201+0000] {taskinstance.py:1380} INFO - Executing <Task(PythonOperator): load> on 2025-09-15 00:00:00+00:00
[2025-09-16T16:23:34.205+0000] {standard_task_runner.py:57} INFO - Started process 114 to run task
[2025-09-16T16:23:34.207+0000] {standard_task_runner.py:84} INFO - Running: ['***', 'tasks', 'run', 'crypto_pipeline_postgres', 'load', 'scheduled__2025-09-15T00:00:00+00:00', '--job-id', '6', '--raw', '--subdir', 'DAGS_FOLDER/coleta_dados.py', '--cfg-path', '/tmp/tmpftbmloq4']
[2025-09-16T16:23:34.208+0000] {standard_task_runner.py:85} INFO - Job 6: Subtask load
[2025-09-16T16:23:34.244+0000] {task_command.py:415} INFO - Running <TaskInstance: crypto_pipeline_postgres.load scheduled__2025-09-15T00:00:00+00:00 [running]> on host 1bf2c2ec56a0
[2025-09-16T16:23:34.299+0000] {taskinstance.py:1660} INFO - Exporting env vars: AIRFLOW_CTX_DAG_OWNER='***' AIRFLOW_CTX_DAG_ID='crypto_pipeline_postgres' AIRFLOW_CTX_TASK_ID='load' AIRFLOW_CTX_EXECUTION_DATE='2025-09-15T00:00:00+00:00' AIRFLOW_CTX_TRY_NUMBER='1' AIRFLOW_CTX_DAG_RUN_ID='scheduled__2025-09-15T00:00:00+00:00'
[2025-09-16T16:23:34.322+0000] {taskinstance.py:1935} ERROR - Task failed with exception
Traceback (most recent call last):
  File "/home/airflow/.local/lib/python3.8/site-packages/airflow/operators/python.py", line 192, in execute
    return_value = self.execute_callable()
  File "/home/airflow/.local/lib/python3.8/site-packages/airflow/operators/python.py", line 209, in execute_callable
    return self.python_callable(*self.op_args, **self.op_kwargs)
  File "/opt/airflow/dags/coleta_dados.py", line 73, in carregar_dados
    engine = hook.get_sqlalchemy_engine()
  File "/home/airflow/.local/lib/python3.8/site-packages/airflow/providers/common/sql/hooks/sql.py", line 199, in get_sqlalchemy_engine
    return create_engine(self.get_uri(), **engine_kwargs)
  File "/home/airflow/.local/lib/python3.8/site-packages/airflow/providers/postgres/hooks/postgres.py", line 185, in get_uri
    conn = self.get_connection(getattr(self, self.conn_name_attr))
  File "/home/airflow/.local/lib/python3.8/site-packages/airflow/hooks/base.py", line 72, in get_connection
    conn = Connection.get_connection_from_secrets(conn_id)
  File "/home/airflow/.local/lib/python3.8/site-packages/airflow/models/connection.py", line 477, in get_connection_from_secrets
    raise AirflowNotFoundException(f"The conn_id `{conn_id}` isn't defined")
airflow.exceptions.AirflowNotFoundException: The conn_id `postgres_default` isn't defined
[2025-09-16T16:23:34.324+0000] {taskinstance.py:1398} INFO - Marking task as UP_FOR_RETRY. dag_id=crypto_pipeline_postgres, task_id=load, execution_date=20250915T000000, start_date=20250916T162334, end_date=20250916T162334
[2025-09-16T16:23:34.331+0000] {standard_task_runner.py:104} ERROR - Failed to execute job 6 for task load (The conn_id `postgres_default` isn't defined; 114)
[2025-09-16T16:23:34.340+0000] {local_task_job_runner.py:228} INFO - Task exited with return code 1
[2025-09-16T16:23:34.351+0000] {taskinstance.py:2776} INFO - 0 downstream tasks scheduled from follow-on schedule check
