[2025-09-16T16:19:17.750+0000] {taskinstance.py:1157} INFO - Dependencies all met for dep_context=non-requeueable deps ti=<TaskInstance: crypto_pipeline_postgres.load manual__2025-09-16T16:13:59.908105+00:00 [queued]>
[2025-09-16T16:19:17.756+0000] {taskinstance.py:1157} INFO - Dependencies all met for dep_context=requeueable deps ti=<TaskInstance: crypto_pipeline_postgres.load manual__2025-09-16T16:13:59.908105+00:00 [queued]>
[2025-09-16T16:19:17.756+0000] {taskinstance.py:1359} INFO - Starting attempt 2 of 2
[2025-09-16T16:19:17.764+0000] {taskinstance.py:1380} INFO - Executing <Task(PythonOperator): load> on 2025-09-16 16:13:59.908105+00:00
[2025-09-16T16:19:17.769+0000] {standard_task_runner.py:57} INFO - Started process 179 to run task
[2025-09-16T16:19:17.771+0000] {standard_task_runner.py:84} INFO - Running: ['***', 'tasks', 'run', 'crypto_pipeline_postgres', 'load', 'manual__2025-09-16T16:13:59.908105+00:00', '--job-id', '9', '--raw', '--subdir', 'DAGS_FOLDER/coleta_dados.py', '--cfg-path', '/tmp/tmp_5gwikc8']
[2025-09-16T16:19:17.772+0000] {standard_task_runner.py:85} INFO - Job 9: Subtask load
[2025-09-16T16:19:17.801+0000] {task_command.py:415} INFO - Running <TaskInstance: crypto_pipeline_postgres.load manual__2025-09-16T16:13:59.908105+00:00 [running]> on host 5a564937ffb3
[2025-09-16T16:19:17.847+0000] {taskinstance.py:1660} INFO - Exporting env vars: AIRFLOW_CTX_DAG_OWNER='***' AIRFLOW_CTX_DAG_ID='crypto_pipeline_postgres' AIRFLOW_CTX_TASK_ID='load' AIRFLOW_CTX_EXECUTION_DATE='2025-09-16T16:13:59.908105+00:00' AIRFLOW_CTX_TRY_NUMBER='2' AIRFLOW_CTX_DAG_RUN_ID='manual__2025-09-16T16:13:59.908105+00:00'
[2025-09-16T16:19:17.849+0000] {taskinstance.py:1935} ERROR - Task failed with exception
Traceback (most recent call last):
  File "/home/airflow/.local/lib/python3.8/site-packages/airflow/operators/python.py", line 192, in execute
    return_value = self.execute_callable()
  File "/home/airflow/.local/lib/python3.8/site-packages/airflow/operators/python.py", line 209, in execute_callable
    return self.python_callable(*self.op_args, **self.op_kwargs)
  File "/opt/airflow/dags/coleta_dados.py", line 59, in carregar_dados
    df = pd.read_csv(TRANSFORMED_CSV_PATH)
  File "/home/airflow/.local/lib/python3.8/site-packages/pandas/io/parsers/readers.py", line 912, in read_csv
    return _read(filepath_or_buffer, kwds)
  File "/home/airflow/.local/lib/python3.8/site-packages/pandas/io/parsers/readers.py", line 577, in _read
    parser = TextFileReader(filepath_or_buffer, **kwds)
  File "/home/airflow/.local/lib/python3.8/site-packages/pandas/io/parsers/readers.py", line 1407, in __init__
    self._engine = self._make_engine(f, self.engine)
  File "/home/airflow/.local/lib/python3.8/site-packages/pandas/io/parsers/readers.py", line 1661, in _make_engine
    self.handles = get_handle(
  File "/home/airflow/.local/lib/python3.8/site-packages/pandas/io/common.py", line 859, in get_handle
    handle = open(
FileNotFoundError: [Errno 2] No such file or directory: '/tmp/crypto_transformed.csv'
[2025-09-16T16:19:17.855+0000] {taskinstance.py:1398} INFO - Marking task as FAILED. dag_id=crypto_pipeline_postgres, task_id=load, execution_date=20250916T161359, start_date=20250916T161917, end_date=20250916T161917
[2025-09-16T16:19:17.861+0000] {standard_task_runner.py:104} ERROR - Failed to execute job 9 for task load ([Errno 2] No such file or directory: '/tmp/crypto_transformed.csv'; 179)
[2025-09-16T16:19:17.903+0000] {local_task_job_runner.py:228} INFO - Task exited with return code 1
[2025-09-16T16:19:17.915+0000] {taskinstance.py:2776} INFO - 0 downstream tasks scheduled from follow-on schedule check
