[2025-09-16T16:09:39.709+0000] {taskinstance.py:1157} INFO - Dependencies all met for dep_context=non-requeueable deps ti=<TaskInstance: crypto_pipeline_postgres.load manual__2025-09-16T16:09:32.190871+00:00 [queued]>
[2025-09-16T16:09:39.714+0000] {taskinstance.py:1157} INFO - Dependencies all met for dep_context=requeueable deps ti=<TaskInstance: crypto_pipeline_postgres.load manual__2025-09-16T16:09:32.190871+00:00 [queued]>
[2025-09-16T16:09:39.715+0000] {taskinstance.py:1359} INFO - Starting attempt 1 of 2
[2025-09-16T16:09:39.723+0000] {taskinstance.py:1380} INFO - Executing <Task(PythonOperator): load> on 2025-09-16 16:09:32.190871+00:00
[2025-09-16T16:09:39.727+0000] {standard_task_runner.py:57} INFO - Started process 273 to run task
[2025-09-16T16:09:39.730+0000] {standard_task_runner.py:84} INFO - Running: ['***', 'tasks', 'run', 'crypto_pipeline_postgres', 'load', 'manual__2025-09-16T16:09:32.190871+00:00', '--job-id', '15', '--raw', '--subdir', 'DAGS_FOLDER/coleta_dados.py', '--cfg-path', '/tmp/tmp5am9tmuj']
[2025-09-16T16:09:39.731+0000] {standard_task_runner.py:85} INFO - Job 15: Subtask load
[2025-09-16T16:09:39.760+0000] {task_command.py:415} INFO - Running <TaskInstance: crypto_pipeline_postgres.load manual__2025-09-16T16:09:32.190871+00:00 [running]> on host 529eb878ec8c
[2025-09-16T16:09:39.809+0000] {taskinstance.py:1660} INFO - Exporting env vars: AIRFLOW_CTX_DAG_OWNER='***' AIRFLOW_CTX_DAG_ID='crypto_pipeline_postgres' AIRFLOW_CTX_TASK_ID='load' AIRFLOW_CTX_EXECUTION_DATE='2025-09-16T16:09:32.190871+00:00' AIRFLOW_CTX_TRY_NUMBER='1' AIRFLOW_CTX_DAG_RUN_ID='manual__2025-09-16T16:09:32.190871+00:00'
[2025-09-16T16:09:39.831+0000] {taskinstance.py:1935} ERROR - Task failed with exception
Traceback (most recent call last):
  File "/home/airflow/.local/lib/python3.8/site-packages/airflow/operators/python.py", line 192, in execute
    return_value = self.execute_callable()
  File "/home/airflow/.local/lib/python3.8/site-packages/airflow/operators/python.py", line 209, in execute_callable
    return self.python_callable(*self.op_args, **self.op_kwargs)
  File "/opt/airflow/dags/coleta_dados.py", line 55, in carregar_dados
    engine = hook.get_sqlalchemy_engine()
  File "/home/airflow/.local/lib/python3.8/site-packages/airflow/providers/common/sql/hooks/sql.py", line 199, in get_sqlalchemy_engine
    return create_engine(self.get_uri(), **engine_kwargs)
  File "/home/airflow/.local/lib/python3.8/site-packages/airflow/providers/postgres/hooks/postgres.py", line 185, in get_uri
    conn = self.get_connection(getattr(self, self.conn_name_attr))
  File "/home/airflow/.local/lib/python3.8/site-packages/airflow/hooks/base.py", line 72, in get_connection
    conn = Connection.get_connection_from_secrets(conn_id)
  File "/home/airflow/.local/lib/python3.8/site-packages/airflow/models/connection.py", line 477, in get_connection_from_secrets
    raise AirflowNotFoundException(f"The conn_id `{conn_id}` isn't defined")
airflow.exceptions.AirflowNotFoundException: The conn_id `postgres_default` isn't defined
[2025-09-16T16:09:39.833+0000] {taskinstance.py:1398} INFO - Marking task as UP_FOR_RETRY. dag_id=crypto_pipeline_postgres, task_id=load, execution_date=20250916T160932, start_date=20250916T160939, end_date=20250916T160939
[2025-09-16T16:09:39.839+0000] {standard_task_runner.py:104} ERROR - Failed to execute job 15 for task load (The conn_id `postgres_default` isn't defined; 273)
[2025-09-16T16:09:39.861+0000] {local_task_job_runner.py:228} INFO - Task exited with return code 1
[2025-09-16T16:09:39.873+0000] {taskinstance.py:2776} INFO - 0 downstream tasks scheduled from follow-on schedule check
